Workbook

Sheet README
A1: THE UNLOX ACADEMY - DA/DS TRACK
A2: Excel Minor Project - Sales Operations Analytics
A3: Interview-Grade Data Analytics Assessment · 100 Marks
A5: THE SCENARIO
A6: You have just joined the analytics team at a fast-growing multi-category retailer operating across 6 Indian cities.
A7: The head of sales has handed you 5 raw data files - Orders, Customers, Products, Sales Reps, and Targets - and asked
A8: you to answer a set of business questions before the leadership review tomorrow morning.
A10: The data is REAL-WORLD messy: duplicates, missing references, inconsistent case, invalid records, discontinued SKUs.
A11: Part of the assessment is spotting and handling these issues correctly. A wrong-looking answer isn't always wrong -
A12: sometimes the data itself is telling a story.
A14: RULES OF THE ASSESSMENT
A15: 1. Write your answer in the YELLOW cells on each question sheet. Empty answer cell = 0 marks.
... A22: MARKS DISTRIBUTION
A23: Section | B23: Topic | C23: Questions | D23: Marks
A24: Q1 | B24: Lookup Functions (VLOOKUP, INDEX-MATCH, chained lookups) | C24: 8 | D24: 25
A25: Q2 | B25: Data Cleaning & Quality Diagnostics | C25: 6 | D25: 20
A26: Q3 | B26: Conditional Aggregation (SUMIFS, COUNTIFS, IF logic) | C26: 6 | D26: 25
A27: Q4 | B27: Pivot Tables (2D pivots, % of total, calculated fields) | C27: 5 | D27: 20
A28: Q5 | B28: Advanced (Ranking, Running Totals, Multi-condition) | C28: 5 | D28: 10
B29: TOTAL | C29: 30 | D29: 100
A32: PERFORMANCE TIERS
A33: Marks | B33: Tier | C33: Interview Verdict
A34: 85 - 100 | B34: Excellent | C34: Round 1 clear - Excel not a concern
A35: 70 - 84 | B35: Good | C35: Round 1 clear with minor gaps
A36: 55 - 69 | B36: Borderline | C36: Round 1 uncertain - needs revision
A37: 40 - 54 | B37: Weak | C37: Round 1 likely reject - 2 weeks of practice needed
A38: < 40 | B38: Insufficient | C38: Round 1 reject - foundational gaps
A41: DATA SHEETS OVERVIEW
A42: Sheet | B42: Rows | C42: Key Columns | D42: Joins to
A43: Orders | B43: ~2000 | C43: order_id, order_date, customer_id, product_id, sales_rep_id, quantity, unit_price, discount_pct, final_amount, payment_status, ship_city | D43: All others
A44: Customers | B44: 300 | C44: customer_id (PK), customer_name, age, city, segment, signup_date | D44: Orders via customer_id
A45: Products | B45: 60 | C45: product_id (PK), product_name, category, unit_cost, unit_price, is_active | D45: Orders via product_id
A46: Sales_Reps | B46: 30 | C46: rep_id (PK), rep_name, region, hire_date, team_lead_id | D46: Orders via sales_rep_id, self-join via team_lead_id
A47: Targets | B47: 30 × 12 | C47: rep_id (PK), Jan-24 through Dec-24 monthly target values | D47: Sales_Reps via rep_id

Sheet Orders
A1: order_id | B1: order_date | C1: customer_id | D1: product_id | E1: sales_rep_id | F1: quantity | G1: unit_price | H1: discount_pct | I1: final_amount | J1: payment_status | K1: ship_city
A2: ORD-00001 | B2: 45549 | C2: CUST-0243 | D2: PROD-014 | E2: R007 | F2: 8 | G2: 3620 | H2: 15.4 | I2: 24500.16 | J2: Completed | K2: Pune
A3: ORD-00002 | B3: 45340 | C3: CUST-0202 | D3: PROD-020 | E3: R005 | F3: 2 | G3: 820 | H3: 10.8 | I3: 1462.88 | J3: Pending | K3: Chennai
A4: ORD-00003 | B4: 45371 | C4: CUST-0098 | D4: PROD-053 | E4: R014 | F4: 8 | G4: 470 | H4: 3.3 | I4: 3635.92 | J4: Pending | K4: Delhi
A5: ORD-00004 | B5: 45413 | C5: CUST-0071 | D5: PROD-028 | E5: R006 | F5: 1 | G5: 3660 | H5: 15.7 | I5: 3085.38 | J5: Completed | K5: Delhi
A6: ORD-00005 | B6: 45611 | C6: CUST-0180 | D6: PROD-012 | E6: R008 | F6: 1 | G6: 3160 | H6: 26 | I6: 2338.4 | J6: Completed | K6: Chennai
A7: ORD-00006 | B7: 45406 | C7: CUST-0275 | D7: PROD-032 | E7: R025 | F7: 4 | G7: 370 | H7: 29 | I7: 1050.8 | J7: Completed | K7: Mumbai
A8: ORD-00007 | B8: 45455 | C8: CUST-0293 | D8: PROD-057 | E8: R024 | F8: 3 | G8: 960 | H8: 5.8 | I8: 2712.96 | J8: Completed | K8: Bengaluru
A9: ORD-00008 | B9: 45617 | C9: CUST-0281 | D9: PROD-007 | E9: R019 | F9: 8 | G9: 1430 | H9: 2.4 | I9: 11165.44 | J9: Completed | K9: Bengaluru
A10: ORD-00009 | B10: 45549 | C10: CUST-0260 | D10: PROD-038 | E10: R008 | F10: 3 | G10: 5490 | H10: 14.2 | I10: 14131.26 | J10: Completed | K10: Bengaluru
A11: ORD-00010 | B11: 45396 | C11: CUST-0147 | D11: PROD-030 | E11: R028 | F11: 3 | G11: 970 | H11: 1.2 | I11: 2875.08 | J11: Completed | K11: Pune
A12: ORD-00011 | B12: 45560 | C12: CUST-0204 | D12: PROD-024 | E12: R010 | F12: 7 | G12: 2270 | H12: 7.1 | I12: 14761.81 | J12: Pending | K12: Hyderabad
A13: ORD-00012 | B13: 45332 | C13: CUST-0147 | D13: PROD-010 | E13: R024 | F13: 9 | G13: 2640 | H13: 21.7 | I13: 18604.08 | J13: Completed | K13: Pune
... A2001: ORD-02000 | B2001: 45325 | C2001: CUST-0238 | D2001: PROD-034 | E2001: R023 | F2001: 6 | G2001: 5080 | H2001: 28.1 | I2001: 21915.12 | J2001: Completed | K2001: Delhi

Sheet Customers
A1: customer_id | B1: customer_name | C1: age | D1: city | E1: segment | F1: signup_date
A2: CUST-0001 | B2: Amit Agarwal | C2: 36 | D2: Pune | E2: Retail | F2: 44819
A3: CUST-0002 | B3: Vihaan Malhotra | C3: 42 | D3: Pune | E3: Corporate | F3: 44984
A4: CUST-0003 | B4: Navya Malhotra | C4: 33 | D4: Mumbai | E4: Retail | F4: 44059
A5: CUST-0004 | B5: Aaradhya Mehta | C5: 53 | D5: delhi | E5: Retail | F5: 44054
A6: CUST-0005 | B6: Myra Malhotra | C6: 52 | D6: Chennai | E6: Corporate | F6: 45037
A7: CUST-0006 | B7: Shaurya Iyer | C7: 44 | D7: Pune | E7: SMB | F7: 44302
A8: CUST-0007 | B8: Dhruv Joshi | C8: 47 | D8: Bengaluru | E8: Retail | F8: 44498
A9: CUST-0008 | B9: Kavita Malhotra | C9: 39 | D9: Pune | E9: SMB | F9: 45162
A10: CUST-0009 | B10: Neha Malhotra | C10: 61 | D10: Mumbai | E10: Retail | F10: 44343
A11: CUST-0010 | B11: Aaradhya Gupta | C11: 61 | D11: Mumbai | E11: SMB | F11: 44975
A12: CUST-0011 | B12: Diya Menon | C12: 41 | D12: Chennai | E12: Corporate | F12: 44821
A13: CUST-0012 | B13: Prisha Desai | C13: 43 | D13: Pune | E13: Retail | F13: 44718
... A301: CUST-0300 | B301: Rohit Nair | C301: 38 | D301: Mumbai | E301: Retail | F301: 43932

Sheet Products
A1: product_id | B1: product_name | C1: category | D1: unit_cost | E1: unit_price | F1: is_active
A2: PROD-001 | B2: Smartphone Pro | C2: Electronics | D2: 2405 | E2: 5330 | F2: =TRUE()
A3: PROD-002 | B3: Wireless Earbuds | C3: Electronics | D3: 1052 | E3: 2600 | F3: =TRUE()
A4: PROD-003 | B4: Smart Watch | C4: Electronics | D4: 1665 | E4: 3570 | F4: =TRUE()
A5: PROD-004 | B5: Laptop Bag | C5: Electronics | D5: 1559 | E5: 3870 | F5: =TRUE()
A6: PROD-005 | B6: Power Bank | C6: Electronics | D6: 128 | E6: 300 | F6: =TRUE()
A7: PROD-006 | B7: Bluetooth Speaker | C7: Electronics | D7: 2865 | E7: 3970 | F7: =TRUE()
A8: PROD-007 | B8: USB-C Cable | C8: Electronics | D8: 861 | E8: 1430 | F8: =TRUE()
A9: PROD-008 | B9: Wireless Mouse | C9: Electronics | D9: 1259 | E9: 2660 | F9: =FALSE()
A10: PROD-009 | B10: Mechanical Keyboard | C10: Electronics | D10: 517 | E10: 1220 | F10: =TRUE()
A11: PROD-010 | B11: Tablet Stand | C11: Electronics | D11: 1149 | E11: 2640 | F11: =TRUE()
A12: PROD-011 | B12: Cotton T-Shirt | C12: Apparel | D12: 1748 | E12: 3450 | F12: =TRUE()
A13: PROD-012 | B13: Denim Jeans | C13: Apparel | D13: 1886 | E13: 3160 | F13: =TRUE()
A14: PROD-013 | B14: Formal Shirt | C14: Apparel | D14: 2611 | E14: 3640 | F14: =TRUE()
A15: PROD-014 | B15: Winter Jacket | C15: Apparel | D15: 2509 | E15: 3620 | F15: =TRUE()
A16: PROD-015 | B16: Sports Shoes | C16: Apparel | D16: 1962 | E16: 2720 | F16: =TRUE()
A17: PROD-016 | B17: Casual Sneakers | C17: Apparel | D17: 396 | E17: 620 | F17: =TRUE()
A18: PROD-017 | B18: Silk Saree | C18: Apparel | D18: 1075 | E18: 2510 | F18: =FALSE()
A19: PROD-018 | B19: Kurta Set | C19: Apparel | D19: 2629 | E19: 3560 | F19: =TRUE()
A20: PROD-019 | B20: Track Pants | C20: Apparel | D20: 1173 | E20: 2480 | F20: =TRUE()
A21: PROD-020 | B21: Woolen Sweater | C21: Apparel | D21: 391 | E21: 820 | F21: =TRUE()
A22: PROD-021 | B22: Basmati Rice 5kg | C22: Grocery | D22: 1435 | E22: 2760 | F22: =TRUE()
A23: PROD-022 | B23: Wheat Flour 10kg | C23: Grocery | D23: 1412 | E23: 2270 | F23: =TRUE()
A24: PROD-023 | B24: Cooking Oil 5L | C24: Grocery | D24: 1182 | E24: 2380 | F24: =TRUE()
A25: PROD-024 | B25: Turmeric Powder 500g | C25: Grocery | D25: 1203 | E25: 2270 | F25: =TRUE()
A26: PROD-025 | B26: Chili Powder 500g | C26: Grocery | D26: 2911 | E26: 4060 | F26: =TRUE()
A27: PROD-026 | B27: Sugar 5kg | C27: Grocery | D27: 2027 | E27: 4070 | F27: =TRUE()
A28: PROD-027 | B28: Tea Leaves 1kg | C28: Grocery | D28: 2436 | E28: 3780 | F28: =TRUE()
A29: PROD-028 | B29: Coffee Beans 500g | C29: Grocery | D29: 2214 | E29: 3660 | F29: =FALSE()
A30: PROD-029 | B30: Ghee 1L | C30: Grocery | D30: 1010 | E30: 2210 | F30: =TRUE()
A31: PROD-030 | B31: Salt 1kg | C31: Grocery | D31: 434 | E31: 970 | F31: =TRUE()
A32: PROD-031 | B32: Bed Sheet Set | C32: Home | D32: 2135 | E32: 3730 | F32: =TRUE()
A33: PROD-032 | B33: Pillow Cover Pair | C33: Home | D33: 288 | E33: 370 | F33: =TRUE()
A34: PROD-033 | B34: Curtain Set | C34: Home | D34: 1143 | E34: 2030 | F34: =TRUE()
A35: PROD-034 | B35: Kitchen Towel Set | C35: Home | D35: 2459 | E35: 5080 | F35: =TRUE()
A36: PROD-035 | B36: Doormat | C36: Home | D36: 464 | E36: 1090 | F36: =TRUE()
A37: PROD-036 | B37: Wall Clock | C37: Home | D37: 1556 | E37: 3250 | F37: =TRUE()
A38: PROD-037 | B38: Table Lamp | C38: Home | D38: 329 | E38: 660 | F38: =TRUE()
A39: PROD-038 | B39: Storage Box | C39: Home | D39: 2549 | E39: 5490 | F39: =TRUE()
A40: PROD-039 | B40: Photo Frame | C40: Home | D40: 1850 | E40: 4610 | F40: =TRUE()
...

Sheet Sales_Reps
A1: rep_id | B1: rep_name | C1: region | D1: hire_date | E1: team_lead_id
A2: R001 | B2: Rajesh Malhotra | C2: North | D2: 44207
A3: R002 | B3: Sunita Malhotra | C3: North | D3: 44028
A4: R003 | B4: Amit Singh | C4: North | D4: 43651
A5: R004 | B5: Priya Singh | C5: North | D5: 44907
A6: R005 | B6: Vikram Patel | C6: North | D6: 43588 | E6: R001
A7: R006 | B7: Neha Desai | C7: North | D7: 44131 | E7: R001
A8: R007 | B8: Suresh Menon | C8: North | D8: 43493 | E8: R001
A9: R008 | B9: Kavita Patel | C9: North | D9: 44693 | E9: R001
A10: R009 | B10: Manoj Patel | C10: South | D10: 44804 | E10: R002
A11: R010 | B11: Divya Rao | C11: South | D11: 43904 | E11: R002
A12: R011 | B12: Anil Verma | C12: South | D12: 44622 | E12: R002
A13: R012 | B13: Pooja Nair | C13: South | D13: 44890 | E13: R002
A14: R013 | B14: Sanjay Kapoor | C14: South | D14: 45215 | E14: R002
A15: R014 | B15: Ritu Menon | C15: South | D15: 44469 | E15: R002
A16: R015 | B16: Deepak Shah | C16: South | D16: 45231 | E16: R002
A17: R016 | B17: Anjali Chopra | C17: South | D17: 43614 | E17: R002
... A31: R030 | B31: Kiran Bhatt | C31: West | D31: 44506 | E31: R004

Sheet Targets
A1: rep_id | B1: Jan-24 | C1: Feb-24 | D1: Mar-24 | E1: Apr-24 | F1: May-24 | G1: Jun-24 | H1: Jul-24 | I1: Aug-24 | J1: Sep-24 | K1: Oct-24 | L1: Nov-24 | M1: Dec-24
A2: R001 | B2: 231324 | C2: 171682 | D2: 234376 | E2: 326967 | F2: 350588 | G2: 385324 | H2: 307980 | I2: 327947 | J2: 181016 | K2: 374039 | L2: 212805 | M2: 405999
A3: R002 | B3: 438126 | C3: 346266 | D3: 329993 | E3: 370744 | F3: 294660 | G3: 341556 | H3: 151934 | I3: 223794 | J3: 438641 | K3: 344308 | L3: 296172 | M3: 304288
A4: R003 | B4: 358703 | C4: 320519 | D4: 327321 | E4: 298753 | F4: 254636 | G4: 351929 | H4: 264723 | I4: 216459 | J4: 391945 | K4: 362426 | L4: 289199 | M4: 301863
A5: R004 | B5: 389594 | C5: 376422 | D5: 324156 | E5: 420255 | F5: 409107 | G5: 269954 | H5: 179097 | I5: 370568 | J5: 387395 | K5: 243454 | L5: 232530 | M5: 201999
A6: R005 | B6: 436862 | C6: 391158 | D6: 340224 | E6: 170548 | F6: 229390 | G6: 349525 | H6: 154683 | I6: 320848 | J6: 354452 | K6: 377180 | L6: 342347 | M6: 183362
A7: R006 | B7: 348734 | C7: 358191 | D7: 250385 | E7: 219657 | F7: 249365 | G7: 435704 | H7: 260892 | I7: 250741 | J7: 358402 | K7: 379858 | L7: 213280 | M7: 224634
A8: R007 | B8: 280057 | C8: 330342 | D8: 336856 | E8: 227425 | F8: 233647 | G8: 307088 | H8: 370724 | I8: 440008 | J8: 406347 | K8: 217357 | L8: 299289 | M8: 214568
A9: R008 | B9: 252886 | C9: 206057 | D9: 318209 | E9: 411230 | F9: 448660 | G9: 171135 | H9: 305339 | I9: 432264 | J9: 294273 | K9: 371409 | L9: 284207 | M9: 437068
A10: R009 | B10: 268752 | C10: 393256 | D10: 310649 | E10: 246237 | F10: 271287 | G10: 314545 | H10: 406506 | I10: 334930 | J10: 348625 | K10: 408928 | L10: 243749 | M10: 418409
A11: R010 | B11: 384734 | C11: 156698 | D11: 283679 | E11: 276085 | F11: 409270 | G11: 285230 | H11: 304233 | I11: 178221 | J11: 284216 | K11: 287373 | L11: 229082 | M11: 298969
A12: R011 | B12: 186029 | C12: 151419 | D12: 253251 | E12: 379757 | F12: 204209 | G12: 179396 | H12: 378008 | I12: 182649 | J12: 267772 | K12: 350352 | L12: 358042 | M12: 359960
A13: R012 | B13: 352158 | C13: 251181 | D13: 321255 | E13: 300863 | F13: 241731 | G13: 393275 | H13: 313561 | I13: 283604 | J13: 429065 | K13: 194420 | L13: 254168 | M13: 389283
... A31: R030 | B31: 151584 | C31: 221679 | D31: 385157 | E31: 290386 | F31: 236041 | G31: 407985 | H31: 184446 | I31: 342894 | J31: 180344 | K31: 292917 | L31: 314858 | M31: 364057

Sheet Q1_Lookups
A1: Q1 - LOOKUP FUNCTIONS (25 marks total)
A2: VLOOKUP · INDEX-MATCH · Two-way lookup · Chain lookup · Approximate lookup · Self-join
A4: Q# | B4: Question | C4: Marks | D4: Hint | E4: Your Answer | F4: Format
A5: Q1.1 | B5: For order ORD-00234, what is the customer_id? | C5: 3 | D5: Simple VLOOKUP on Orders sheet. | E5: CUST-0173 | F5: CUST-####
A6: Q1.2 | B6: For order ORD-00456, what is the product_name? (You will need to look up the product_id first, then find its name in Products.) | C6: 3 | D6: Two-step lookup, or nested VLOOKUP. | E6: Dumbbells 5kg | F6: Text
A7: Q1.3 | B7: For order ORD-00987, what is the rep_name of the sales rep? Note: the rep_name is in a column that appears to the LEFT of what you might look up first. | C7: 3 | D7: VLOOKUP has directional limits - INDEX/MATCH does not. | E7: Nisha Menon | F7: Text
A8: Q1.4 | B8: From the Targets sheet, what is the target value for rep R012 in the month Mar-24? | C8: 4 | D8: Two-way lookup: row = rep_id, column = month. | E8: 321255 | F8: Whole number
A9: Q1.5 | B9: For order ORD-01500, what is the CATEGORY of the product ordered? (Chain: order → product_id → category) | C9: 4 | D9: Multi-hop lookup across sheets. | E9: Electronics | F9: Text
A10: Q1.6 | B10: For order ORD-00789, which DISCOUNT SLAB does it fall in? Use the slab table below (rows 20-24). Slab breakpoints are the LOWER bound of each range. | C10: 3 | D10: Approximate-match VLOOKUP (sort ascending, TRUE / omit last arg). | E10: Bronze | F10: Text
A11: Q1.7 | B11: For order ORD-01234, in one cell produce the string: "<rep_name> (<sales_region>)" - e.g. "Amit Singh (South)". | C11: 3 | D11: Two lookups joined with & or CONCATENATE. | E11: Sanjay Kapoor (South) | F11: Text
A12: Q1.8 | B12: What is the rep_name of the TEAM LEAD for rep R017? (The Sales_Reps sheet has team_lead_id - you need to self-join to find that person's name.) | C12: 2 | D12: Look up the team_lead_id, then look up THAT id's rep_name. | E12: Amit Singh | F12: Text
B15: DISCOUNT SLAB REFERENCE TABLE (use for Q1.6)
B17: Discount % (Lower) | C17: Slab
B18: 0 | C18: Bronze
B19: 5 | C19: Silver
B20: 15 | C20: Gold
B21: 25 | C21: Platinum

Sheet Q2_Cleaning
A1: Q2 - DATA CLEANING & QUALITY DIAGNOSTICS (20 marks total)
A2: Duplicates · Whitespace · Case Inconsistency · Referential Integrity · Discontinued SKUs · Anomaly Patterns
A4: Q# | B4: Question | C4: Marks | D4: Hint | E4: Your Answer | F4: Format
A5: Q2.1 | B5: How many DUPLICATE rows exist in the Orders sheet (i.e., how many order_id values appear more than once)? Count each duplicate as ONE (not the extras). | C5: 3 | D5: COUNTIF > 1, then count. Watch what you're counting - rows or IDs. | E5: 20 | F5: Whole number
A6: Q2.2 | B6: How many customers in the Customers sheet have LEADING or TRAILING whitespace in their customer_name? | C6: 3 | D6: Compare LEN vs LEN(TRIM). Or use SUMPRODUCT with a boolean. | E6: 15 | F6: Whole number
A7: Q2.3 | B7: The Customers sheet has some cities in inconsistent case (e.g., "mumbai", "MUMBAI", "Mumbai"). How many DISTINCT cities exist AFTER standardizing case? | C7: 3 | D7: Combine PROPER/UPPER with a de-dup count. SUMPRODUCT + 1/COUNTIF trick works. | E7: 6 | F7: Whole number
A8: Q2.4 | B8: How many orders reference a customer_id that DOES NOT EXIST in the Customers sheet? (Broken foreign key) | C8: 4 | D8: Use MATCH with ISNA/ISERROR, then count. | E8: 30 | F8: Whole number
A9: Q2.5 | B9: How many orders reference a product that is currently DISCONTINUED (is_active = FALSE in the Products sheet)? | C9: 3 | D9: VLOOKUP the is_active flag, then count where FALSE. | E9: 174 | F9: Whole number
A10: Q2.6 | B10: Find the "suspicious pattern": how many orders have payment_status = "Cancelled" AND a discount_pct > 20%? (This pattern often indicates promo abuse - a real-world diagnostic query.) | C10: 4 | D10: COUNTIFS with two criteria. | E10: 58 | F10: Whole number

Sheet Q3_Aggregation
A1: Q3 - CONDITIONAL AGGREGATION (25 marks total)
A2: SUMIFS · COUNTIFS · AVERAGEIFS · Nested IF logic · Multi-sheet aggregation · Top-N logic
A4: Q# | B4: Question | C4: Marks | D4: Hint | E4: Your Answer | F4: Format
A5: Q3.1 | B5: What is the TOTAL REVENUE (sum of final_amount) for orders in Q3 2024 (Jul-Sep) where ship_city is Mumbai? | C5: 4 | D5: SUMIFS with 3 conditions: date >= start, date <= end, city = Mumbai. Beware case issues. | E5: 1217239 | F5: Currency
A6: Q3.2 | B6: How many orders have discount_pct > 15% AND payment_status = "Completed"? | C6: 3 | D6: COUNTIFS with two conditions. | E6: 723 | F6: Whole number
A7: Q3.3 | B7: What is the AVERAGE final_amount for orders where the product CATEGORY is "Electronics" AND the customer SEGMENT is "Corporate"? Note: Both fields come from OTHER sheets - you'll need helper columns. | C7: 5 | D7: Helper columns in Orders: VLOOKUP category from Products, VLOOKUP segment from Customers. Then AVERAGEIFS. | E7: 13981.402 | F7: Currency
A8: Q3.4 | B8: What is the COMBINED REVENUE of the TOP 3 reps by total revenue? (Sum of the 3 highest rep totals.) | C8: 4 | D8: Compute per-rep totals, then use SUMPRODUCT with LARGE, or sort and sum top 3. | E8: 3342678.5 | F8: Currency
A9: Q3.5 | B9: For rep R015 in Nov-24: compute the actual revenue and compare to the target (from Targets sheet). Report the PERFORMANCE TIER using: <80% → "Below", 80-120% → "On Track", >120% → "Exceeds". Return only the tier text. | C9: 5 | D9: Nested IF (or IFS): compute actual/target ratio, then classify. | E9: Below | F9: Text
A10: Q3.6 | B10: What is the TOTAL revenue from Corporate segment customers aged between 30 and 40 (both inclusive)? | C10: 4 | D10: Helper columns for age and segment. Then SUMIFS with numeric range. | E10: 982568.4 | F10: Currency

Sheet Q4_Pivot
A1: Q4 - PIVOT TABLES (20 marks total)
A2: 2D Pivots · Filters · % of Row Total · Date Grouping · Calculated Fields · Cross-Sheet Data
A4: Q# | B4: Question | C4: Marks | D4: Hint | E4: Your Answer | F4: Format
A5: Q4.1 | B5: Build a pivot with sales_region as rows and product category as columns, values = SUM of final_amount. What value appears at the intersection of "South" and "Electronics"? | C5: 4 | D5: You need to add category (from Products) and region (from Sales_Reps) as columns to Orders first. Insert PivotTable from combined data. | E5: 1314107.4 | F5: Currency
A6: Q4.2 | B6: Build a pivot: rows = order month (Jan-24 through Dec-24), columns = sales_rep_id, values = SUM of final_amount. What is the HIGHEST single value in the entire pivot? (One number.) | C6: 4 | D6: After building, use MAX() over the pivot data range, or scan visually. | E6: 216421.52 | F6: Currency
A7: Q4.3 | B7: For the North sales_region only: what PERCENTAGE of total revenue comes from the Apparel category? Configure the pivot with Show Values As → % of Row Total. | C7: 4 | D7: Pivot: rows=region, cols=category, values=sum(final_amount), Show Values As = % of Row Total. | E7: 0.1402315 | F7: Percentage
A8: Q4.4 | B8: Group order dates by QUARTER in a pivot. What is the total revenue for Q4 2024 (Oct-Dec)? | C8: 4 | D8: PivotTable → Group By → Quarter. Or SUMIFS with date range. | E8: 6459443 | F8: Currency
A9: Q4.5 | B9: Create a CALCULATED FIELD in the pivot: profit_margin = (unit_price - unit_cost) / unit_price. What is the AVERAGE profit_margin for orders shipped to Delhi? Give as a percentage. | C9: 4 | D9: Add unit_cost via VLOOKUP as helper column. Create pivot calculated field, filter to Delhi. | E9: 0.44903865 | F9: Percentage

Sheet Q5_Advanced
A1: Q5 - ADVANCED (10 marks total)
A2: RANK · Running Totals · TEXTJOIN · LARGE + INDEX/MATCH · Multi-condition top-N
A4: Q# | B4: Question | C4: Marks | D4: Hint | E4: Your Answer | F4: Format
A5: Q5.1 | B5: Rank all sales reps by total revenue (highest = rank 1). Who (name) is at RANK #7? | C5: 2 | D5: Per-rep totals, then use RANK.EQ, or sort. Return the rep_name at position 7. | E5: Amit Singh | F5: Text
A6: Q5.2 | B6: What is the CUMULATIVE revenue from Jan 2024 through the end of Aug 2024? (Sum of final_amount where order_date <= 31-Aug-2024.) | C6: 2 | D6: SUMIFS with date <=. | E6: 18050690 | F6: Currency
A7: Q5.3 | B7: Among orders where the sales rep is in the WEST region: which product (by name) has the 2nd highest total revenue? | C7: 3 | D7: Helper: sales_region on orders. Filter/pivot to West, sum by product, rank, get #2, VLOOKUP product name. | E7: Smart Watch | F7: Text
A8: Q5.4 | B8: Concatenate the names of the top 5 reps by revenue into a single cell, separated by " | " (space-pipe-space). | C8: 2 | D8: TEXTJOIN with delimiter " | ". Combine with LARGE to pull top 5. | E8: Neha Desai | Shalini Patel | Deepak Shah | Nisha Menon | Arun Iyer | F8: Text
A9: Q5.5 | B9: What is the HIGHEST single order value (final_amount) where ship_city = "Bengaluru" AND the product's category = "Grocery"? | C9: 1 | D9: MAXIFS with a category helper column, or nested MAX(IF()). | E9: 22134 | F9: Currency

Sheet Analysis_Helper
A1: order_id | B1: order_date | C1: customer_id | D1: product_id | E1: sales_rep_id | F1: quantity | G1: unit_price | H1: discount_pct | I1: final_amount | J1: payment_status | K1: ship_city | L1: product_category | M1: customer_segment | N1: sales_region | O1: unit_cost | P1: customer_age | Q1: city_std | R1: profit_margin | S1: is_active | U1: customer_name_trimmed | V1: customer_city_std | W1: has_name_whitespace | Y1: Supporting calculations
A2: =Orders!A2 | B2: =Orders!B2 | C2: =Orders!C2 | D2: =Orders!D2 | E2: =Orders!E2 | F2: =Orders!F2 | G2: =Orders!G2 | H2: =Orders!H2 | ... K2: =Orders!K2 | L2: =VLOOKUP(D2,Products!$A$2:$F$61,3,FALSE()) | M2: =VLOOKUP(C2,Customers!$A$2:$F$301,5,FALSE()) | N2: =VLOOKUP(E2,Sales_Reps!$A$2:$E$31,3,FALSE()) | O2: =VLOOKUP(D2,Products!$A$2:$F$61,4,FALSE()) | P2: =VLOOKUP(C2,Customers!$A$2:$F$301,3,FALSE()) | Q2: =UPPER(TRIM(K2)) | R2: =(G2-O2)/G2 | S2: =VLOOKUP(D2,Products!$A$2:$F$61,6,FALSE()) | U2: =TRIM(Customers!B2) | V2: =UPPER(TRIM(Customers!D2)) | W2: =LEN(Customers!B2)<>LEN(TRIM(Customers!B2)) | Y2: The original DATA sheets were not modified. Helper and pivot sheets were added only for analysis/support.
A3: =Orders!A3 | B3: =Orders!B3 | C3: =Orders!C3 | D3: =Orders!D3 | E3: =Orders!E3 | F3: =Orders!F3 | G3: =Orders!G3 | H3: =Orders!H3 | ... K3: =Orders!K3 | L3: =VLOOKUP(D3,Products!$A$2:$F$61,3,FALSE()) | M3: =VLOOKUP(C3,Customers!$A$2:$F$301,5,FALSE()) | N3: =VLOOKUP(E3,Sales_Reps!$A$2:$E$31,3,FALSE()) | O3: =VLOOKUP(D3,Products!$A$2:$F$61,4,FALSE()) | P3: =VLOOKUP(C3,Customers!$A$2:$F$301,3,FALSE()) | Q3: =UPPER(TRIM(K3)) | R3: =(G3-O3)/G3 | S3: =VLOOKUP(D3,Products!$A$2:$F$61,6,FALSE()) | U3: =TRIM(Customers!B3) | V3: =UPPER(TRIM(Customers!D3)) | W3: =LEN(Customers!B3)<>LEN(TRIM(Customers!B3))
A4: =Orders!A4 | B4: =Orders!B4 | C4: =Orders!C4 | D4: =Orders!D4 | E4: =Orders!E4 | F4: =Orders!F4 | G4: =Orders!G4 | H4: =Orders!H4 | ... K4: =Orders!K4 | L4: =VLOOKUP(D4,Products!$A$2:$F$61,3,FALSE()) | M4: =VLOOKUP(C4,Customers!$A$2:$F$301,5,FALSE()) | N4: =VLOOKUP(E4,Sales_Reps!$A$2:$E$31,3,FALSE()) | O4: =VLOOKUP(D4,Products!$A$2:$F$61,4,FALSE()) | P4: =VLOOKUP(C4,Customers!$A$2:$F$301,3,FALSE()) | Q4: =UPPER(TRIM(K4)) | R4: =(G4-O4)/G4 | S4: =VLOOKUP(D4,Products!$A$2:$F$61,6,FALSE()) | U4: =TRIM(Customers!B4) | V4: =UPPER(TRIM(Customers!D4)) | W4: =LEN(Customers!B4)<>LEN(TRIM(Customers!B4))
A5: =Orders!A5 | B5: =Orders!B5 | C5: =Orders!C5 | D5: =Orders!D5 | E5: =Orders!E5 | F5: =Orders!F5 | G5: =Orders!G5 | H5: =Orders!H5 | ... K5: =Orders!K5 | L5: =VLOOKUP(D5,Products!$A$2:$F$61,3,FALSE()) | M5: =VLOOKUP(C5,Customers!$A$2:$F$301,5,FALSE()) | N5: =VLOOKUP(E5,Sales_Reps!$A$2:$E$31,3,FALSE()) | O5: =VLOOKUP(D5,Products!$A$2:$F$61,4,FALSE()) | P5: =VLOOKUP(C5,Customers!$A$2:$F$301,3,FALSE()) | Q5: =UPPER(TRIM(K5)) | R5: =(G5-O5)/G5 | S5: =VLOOKUP(D5,Products!$A$2:$F$61,6,FALSE()) | U5: =TRIM(Customers!B5) | V5: =UPPER(TRIM(Customers!D5)) | W5: =LEN(Customers!B5)<>LEN(TRIM(Customers!B5))
A6: =Orders!A6 | B6: =Orders!B6 | C6: =Orders!C6 | D6: =Orders!D6 | E6: =Orders!E6 | F6: =Orders!F6 | G6: =Orders!G6 | H6: =Orders!H6 | ... K6: =Orders!K6 | L6: =VLOOKUP(D6,Products!$A$2:$F$61,3,FALSE()) | M6: =VLOOKUP(C6,Customers!$A$2:$F$301,5,FALSE()) | N6: =VLOOKUP(E6,Sales_Reps!$A$2:$E$31,3,FALSE()) | O6: =VLOOKUP(D6,Products!$A$2:$F$61,4,FALSE()) | P6: =VLOOKUP(C6,Customers!$A$2:$F$301,3,FALSE()) | Q6: =UPPER(TRIM(K6)) | R6: =(G6-O6)/G6 | S6: =VLOOKUP(D6,Products!$A$2:$F$61,6,FALSE()) | U6: =TRIM(Customers!B6) | V6: =UPPER(TRIM(Customers!D6)) | W6: =LEN(Customers!B6)<>LEN(TRIM(Customers!B6))
A7: =Orders!A7 | B7: =Orders!B7 | C7: =Orders!C7 | D7: =Orders!D7 | E7: =Orders!E7 | F7: =Orders!F7 | G7: =Orders!G7 | H7: =Orders!H7 | ... K7: =Orders!K7 | L7: =VLOOKUP(D7,Products!$A$2:$F$61,3,FALSE()) | M7: =VLOOKUP(C7,Customers!$A$2:$F$301,5,FALSE()) | N7: =VLOOKUP(E7,Sales_Reps!$A$2:$E$31,3,FALSE()) | O7: =VLOOKUP(D7,Products!$A$2:$F$61,4,FALSE()) | P7: =VLOOKUP(C7,Customers!$A$2:$F$301,3,FALSE()) | Q7: =UPPER(TRIM(K7)) | R7: =(G7-O7)/G7 | S7: =VLOOKUP(D7,Products!$A$2:$F$61,6,FALSE()) | U7: =TRIM(Customers!B7) | V7: =UPPER(TRIM(Customers!D7)) | W7: =LEN(Customers!B7)<>LEN(TRIM(Customers!B7))
A8: =Orders!A8 | B8: =Orders!B8 | C8: =Orders!C8 | D8: =Orders!D8 | E8: =Orders!E8 | F8: =Orders!F8 | G8: =Orders!G8 | H8: =Orders!H8 | ... K8: =Orders!K8 | L8: =VLOOKUP(D8,Products!$A$2:$F$61,3,FALSE()) | M8: =VLOOKUP(C8,Customers!$A$2:$F$301,5,FALSE()) | N8: =VLOOKUP(E8,Sales_Reps!$A$2:$E$31,3,FALSE()) | O8: =VLOOKUP(D8,Products!$A$2:$F$61,4,FALSE()) | P8: =VLOOKUP(C8,Customers!$A$2:$F$301,3,FALSE()) | Q8: =UPPER(TRIM(K8)) | R8: =(G8-O8)/G8 | S8: =VLOOKUP(D8,Products!$A$2:$F$61,6,FALSE()) | U8: =TRIM(Customers!B8) | V8: =UPPER(TRIM(Customers!D8)) | W8: =LEN(Customers!B8)<>LEN(TRIM(Customers!B8))
A9: =Orders!A9 | B9: =Orders!B9 | C9: =Orders!C9 | D9: =Orders!D9 | E9: =Orders!E9 | F9: =Orders!F9 | G9: =Orders!G9 | H9: =Orders!H9 | ... K9: =Orders!K9 | L9: =VLOOKUP(D9,Products!$A$2:$F$61,3,FALSE()) | M9: =VLOOKUP(C9,Customers!$A$2:$F$301,5,FALSE()) | N9: =VLOOKUP(E9,Sales_Reps!$A$2:$E$31,3,FALSE()) | O9: =VLOOKUP(D9,Products!$A$2:$F$61,4,FALSE()) | P9: =VLOOKUP(C9,Customers!$A$2:$F$301,3,FALSE()) | Q9: =UPPER(TRIM(K9)) | R9: =(G9-O9)/G9 | S9: =VLOOKUP(D9,Products!$A$2:$F$61,6,FALSE()) | U9: =TRIM(Customers!B9) | V9: =UPPER(TRIM(Customers!D9)) | W9: =LEN(Customers!B9)<>LEN(TRIM(Customers!B9))
A10: =Orders!A10 | B10: =Orders!B10 | C10: =Orders!C10 | D10: =Orders!D10 | E10: =Orders!E10 | F10: =Orders!F10 | G10: =Orders!G10 | H10: =Orders!H10 | ... K10: =Orders!K10 | L10: =VLOOKUP(D10,Products!$A$2:$F$61,3,FALSE()) | M10: =VLOOKUP(C10,Customers!$A$2:$F$301,5,FALSE()) | N10: =VLOOKUP(E10,Sales_Reps!$A$2:$E$31,3,FALSE()) | O10: =VLOOKUP(D10,Products!$A$2:$F$61,4,FALSE()) | P10: =VLOOKUP(C10,Customers!$A$2:$F$301,3,FALSE()) | Q10: =UPPER(TRIM(K10)) | R10: =(G10-O10)/G10 | S10: =VLOOKUP(D10,Products!$A$2:$F$61,6,FALSE()) | U10: =TRIM(Customers!B10) | V10: =UPPER(TRIM(Customers!D10)) | W10: =LEN(Customers!B10)<>LEN(TRIM(Customers!B10))
A11: =Orders!A11 | B11: =Orders!B11 | C11: =Orders!C11 | D11: =Orders!D11 | E11: =Orders!E11 | F11: =Orders!F11 | G11: =Orders!G11 | H11: =Orders!H11 | ... K11: =Orders!K11 | L11: =VLOOKUP(D11,Products!$A$2:$F$61,3,FALSE()) | M11: =VLOOKUP(C11,Customers!$A$2:$F$301,5,FALSE()) | N11: =VLOOKUP(E11,Sales_Reps!$A$2:$E$31,3,FALSE()) | O11: =VLOOKUP(D11,Products!$A$2:$F$61,4,FALSE()) | P11: =VLOOKUP(C11,Customers!$A$2:$F$301,3,FALSE()) | Q11: =UPPER(TRIM(K11)) | R11: =(G11-O11)/G11 | S11: =VLOOKUP(D11,Products!$A$2:$F$61,6,FALSE()) | U11: =TRIM(Customers!B11) | V11: =UPPER(TRIM(Customers!D11)) | W11: =LEN(Customers!B11)<>LEN(TRIM(Customers!B11))
A12: =Orders!A12 | B12: =Orders!B12 | C12: =Orders!C12 | D12: =Orders!D12 | E12: =Orders!E12 | F12: =Orders!F12 | G12: =Orders!G12 | H12: =Orders!H12 | ... K12: =Orders!K12 | L12: =VLOOKUP(D12,Products!$A$2:$F$61,3,FALSE()) | M12: =VLOOKUP(C12,Customers!$A$2:$F$301,5,FALSE()) | N12: =VLOOKUP(E12,Sales_Reps!$A$2:$E$31,3,FALSE()) | O12: =VLOOKUP(D12,Products!$A$2:$F$61,4,FALSE()) | P12: =VLOOKUP(C12,Customers!$A$2:$F$301,3,FALSE()) | Q12: =UPPER(TRIM(K12)) | R12: =(G12-O12)/G12 | S12: =VLOOKUP(D12,Products!$A$2:$F$61,6,FALSE()) | U12: =TRIM(Customers!B12) | V12: =UPPER(TRIM(Customers!D12)) | W12: =LEN(Customers!B12)<>LEN(TRIM(Customers!B12))
A13: =Orders!A13 | B13: =Orders!B13 | C13: =Orders!C13 | D13: =Orders!D13 | E13: =Orders!E13 | F13: =Orders!F13 | G13: =Orders!G13 | H13: =Orders!H13 | ... K13: =Orders!K13 | L13: =VLOOKUP(D13,Products!$A$2:$F$61,3,FALSE()) | M13: =VLOOKUP(C13,Customers!$A$2:$F$301,5,FALSE()) | N13: =VLOOKUP(E13,Sales_Reps!$A$2:$E$31,3,FALSE()) | O13: =VLOOKUP(D13,Products!$A$2:$F$61,4,FALSE()) | P13: =VLOOKUP(C13,Customers!$A$2:$F$301,3,FALSE()) | Q13: =UPPER(TRIM(K13)) | R13: =(G13-O13)/G13 | S13: =VLOOKUP(D13,Products!$A$2:$F$61,6,FALSE()) | U13: =TRIM(Customers!B13) | V13: =UPPER(TRIM(Customers!D13)) | W13: =LEN(Customers!B13)<>LEN(TRIM(Customers!B13))
A14: =Orders!A14 | B14: =Orders!B14 | C14: =Orders!C14 | D14: =Orders!D14 | E14: =Orders!E14 | F14: =Orders!F14 | G14: =Orders!G14 | H14: =Orders!H14 | ... K14: =Orders!K14 | L14: =VLOOKUP(D14,Products!$A$2:$F$61,3,FALSE()) | M14: =VLOOKUP(C14,Customers!$A$2:$F$301,5,FALSE()) | N14: =VLOOKUP(E14,Sales_Reps!$A$2:$E$31,3,FALSE()) | O14: =VLOOKUP(D14,Products!$A$2:$F$61,4,FALSE()) | P14: =VLOOKUP(C14,Customers!$A$2:$F$301,3,FALSE()) | Q14: =UPPER(TRIM(K14)) | R14: =(G14-O14)/G14 | S14: =VLOOKUP(D14,Products!$A$2:$F$61,6,FALSE()) | U14: =TRIM(Customers!B14) | V14: =UPPER(TRIM(Customers!D14)) | W14: =LEN(Customers!B14)<>LEN(TRIM(Customers!B14))
... A301: =Orders!A301 | B301: =Orders!B301 | C301: =Orders!C301 | D301: =Orders!D301 | E301: =Orders!E301 | F301: =Orders!F301 | G301: =Orders!G301 | H301: =Orders!H301 | ... K301: =Orders!K301 | L301: =VLOOKUP(D301,Products!$A$2:$F$61,3,FALSE()) | M301: =VLOOKUP(C301,Customers!$A$2:$F$301,5,FALSE()) | N301: =VLOOKUP(E301,Sales_Reps!$A$2:$E$31,3,FALSE()) | O301: =VLOOKUP(D301,Products!$A$2:$F$61,4,FALSE()) | P301: =VLOOKUP(C301,Customers!$A$2:$F$301,3,FALSE()) | Q301: =UPPER(TRIM(K301)) | R301: =(G301-O301)/G301 | S301: =VLOOKUP(D301,Products!$A$2:$F$61,6,FALSE()) | U301: =TRIM(Customers!B301) | V301: =UPPER(TRIM(Customers!D301)) | W301: =LEN(Customers!B301)<>LEN(TRIM(Customers!B301))
A302: =Orders!A302 | B302: =Orders!B302 | C302: =Orders!C302 | D302: =Orders!D302 | E302: =Orders!E302 | F302: =Orders!F302 | G302: =Orders!G302 | H302: =Orders!H302 | ... K302: =Orders!K302 | L302: =VLOOKUP(D302,Products!$A$2:$F$61,3,FALSE()) | M302: =VLOOKUP(C302,Customers!$A$2:$F$301,5,FALSE()) | N302: =VLOOKUP(E302,Sales_Reps!$A$2:$E$31,3,FALSE()) | O302: =VLOOKUP(D302,Products!$A$2:$F$61,4,FALSE()) | P302: =VLOOKUP(C302,Customers!$A$2:$F$301,3,FALSE()) | Q302: =UPPER(TRIM(K302)) | R302: =(G302-O302)/G302 | S302: =VLOOKUP(D302,Products!$A$2:$F$61,6,FALSE())
A303: =Orders!A303 | B303: =Orders!B303 | C303: =Orders!C303 | D303: =Orders!D303 | E303: =Orders!E303 | F303: =Orders!F303 | G303: =Orders!G303 | H303: =Orders!H303 | ... K303: =Orders!K303 | L303: =VLOOKUP(D303,Products!$A$2:$F$61,3,FALSE()) | M303: =VLOOKUP(C303,Customers!$A$2:$F$301,5,FALSE()) | N303: =VLOOKUP(E303,Sales_Reps!$A$2:$E$31,3,FALSE()) | O303: =VLOOKUP(D303,Products!$A$2:$F$61,4,FALSE()) | P303: =VLOOKUP(C303,Customers!$A$2:$F$301,3,FALSE()) | Q303: =UPPER(TRIM(K303)) | R303: =(G303-O303)/G303 | S303: =VLOOKUP(D303,Products!$A$2:$F$61,6,FALSE())
A304: =Orders!A304 | B304: =Orders!B304 | C304: =Orders!C304 | D304: =Orders!D304 | E304: =Orders!E304 | F304: =Orders!F304 | G304: =Orders!G304 | H304: =Orders!H304 | ... K304: =Orders!K304 | L304: =VLOOKUP(D304,Products!$A$2:$F$61,3,FALSE()) | M304: =VLOOKUP(C304,Customers!$A$2:$F$301,5,FALSE()) | N304: =VLOOKUP(E304,Sales_Reps!$A$2:$E$31,3,FALSE()) | O304: =VLOOKUP(D304,Products!$A$2:$F$61,4,FALSE()) | P304: =VLOOKUP(C304,Customers!$A$2:$F$301,3,FALSE()) | Q304: =UPPER(TRIM(K304)) | R304: =(G304-O304)/G304 | S304: =VLOOKUP(D304,Products!$A$2:$F$61,6,FALSE())
A305: =Orders!A305 | B305: =Orders!B305 | C305: =Orders!C305 | D305: =Orders!D305 | E305: =Orders!E305 | F305: =Orders!F305 | G305: =Orders!G305 | H305: =Orders!H305 | ... K305: =Orders!K305 | L305: =VLOOKUP(D305,Products!$A$2:$F$61,3,FALSE()) | M305: =VLOOKUP(C305,Customers!$A$2:$F$301,5,FALSE()) | N305: =VLOOKUP(E305,Sales_Reps!$A$2:$E$31,3,FALSE()) | O305: =VLOOKUP(D305,Products!$A$2:$F$61,4,FALSE()) | P305: =VLOOKUP(C305,Customers!$A$2:$F$301,3,FALSE()) | Q305: =UPPER(TRIM(K305)) | R305: =(G305-O305)/G305 | S305: =VLOOKUP(D305,Products!$A$2:$F$61,6,FALSE())
A306: =Orders!A306 | B306: =Orders!B306 | C306: =Orders!C306 | D306: =Orders!D306 | E306: =Orders!E306 | F306: =Orders!F306 | G306: =Orders!G306 | H306: =Orders!H306 | ... K306: =Orders!K306 | L306: =VLOOKUP(D306,Products!$A$2:$F$61,3,FALSE()) | M306: =VLOOKUP(C306,Customers!$A$2:$F$301,5,FALSE()) | N306: =VLOOKUP(E306,Sales_Reps!$A$2:$E$31,3,FALSE()) | O306: =VLOOKUP(D306,Products!$A$2:$F$61,4,FALSE()) | P306: =VLOOKUP(C306,Customers!$A$2:$F$301,3,FALSE()) | Q306: =UPPER(TRIM(K306)) | R306: =(G306-O306)/G306 | S306: =VLOOKUP(D306,Products!$A$2:$F$61,6,FALSE())
A307: =Orders!A307 | B307: =Orders!B307 | C307: =Orders!C307 | D307: =Orders!D307 | E307: =Orders!E307 | F307: =Orders!F307 | G307: =Orders!G307 | H307: =Orders!H307 | ... K307: =Orders!K307 | L307: =VLOOKUP(D307,Products!$A$2:$F$61,3,FALSE()) | M307: =VLOOKUP(C307,Customers!$A$2:$F$301,5,FALSE()) | N307: =VLOOKUP(E307,Sales_Reps!$A$2:$E$31,3,FALSE()) | O307: =VLOOKUP(D307,Products!$A$2:$F$61,4,FALSE()) | P307: =VLOOKUP(C307,Customers!$A$2:$F$301,3,FALSE()) | Q307: =UPPER(TRIM(K307)) | R307: =(G307-O307)/G307 | S307: =VLOOKUP(D307,Products!$A$2:$F$61,6,FALSE())
A308: =Orders!A308 | B308: =Orders!B308 | C308: =Orders!C308 | D308: =Orders!D308 | E308: =Orders!E308 | F308: =Orders!F308 | G308: =Orders!G308 | H308: =Orders!H308 | ... K308: =Orders!K308 | L308: =VLOOKUP(D308,Products!$A$2:$F$61,3,FALSE()) | M308: =VLOOKUP(C308,Customers!$A$2:$F$301,5,FALSE()) | N308: =VLOOKUP(E308,Sales_Reps!$A$2:$E$31,3,FALSE()) | O308: =VLOOKUP(D308,Products!$A$2:$F$61,4,FALSE()) | P308: =VLOOKUP(C308,Customers!$A$2:$F$301,3,FALSE()) | Q308: =UPPER(TRIM(K308)) | R308: =(G308-O308)/G308 | S308: =VLOOKUP(D308,Products!$A$2:$F$61,6,FALSE())
A309: =Orders!A309 | B309: =Orders!B309 | C309: =Orders!C309 | D309: =Orders!D309 | E309: =Orders!E309 | F309: =Orders!F309 | G309: =Orders!G309 | H309: =Orders!H309 | ... K309: =Orders!K309 | L309: =VLOOKUP(D309,Products!$A$2:$F$61,3,FALSE()) | M309: =VLOOKUP(C309,Customers!$A$2:$F$301,5,FALSE()) | N309: =VLOOKUP(E309,Sales_Reps!$A$2:$E$31,3,FALSE()) | O309: =VLOOKUP(D309,Products!$A$2:$F$61,4,FALSE()) | P309: =VLOOKUP(C309,Customers!$A$2:$F$301,3,FALSE()) | Q309: =UPPER(TRIM(K309)) | R309: =(G309-O309)/G309 | S309: =VLOOKUP(D309,Products!$A$2:$F$61,6,FALSE())
A310: =Orders!A310 | B310: =Orders!B310 | C310: =Orders!C310 | D310: =Orders!D310 | E310: =Orders!E310 | F310: =Orders!F310 | G310: =Orders!G310 | H310: =Orders!H310 | ... K310: =Orders!K310 | L310: =VLOOKUP(D310,Products!$A$2:$F$61,3,FALSE()) | M310: =VLOOKUP(C310,Customers!$A$2:$F$301,5,FALSE()) | N310: =VLOOKUP(E310,Sales_Reps!$A$2:$E$31,3,FALSE()) | O310: =VLOOKUP(D310,Products!$A$2:$F$61,4,FALSE()) | P310: =VLOOKUP(C310,Customers!$A$2:$F$301,3,FALSE()) | Q310: =UPPER(TRIM(K310)) | R310: =(G310-O310)/G310 | S310: =VLOOKUP(D310,Products!$A$2:$F$61,6,FALSE())
A311: =Orders!A311 | B311: =Orders!B311 | C311: =Orders!C311 | D311: =Orders!D311 | E311: =Orders!E311 | F311: =Orders!F311 | G311: =Orders!G311 | H311: =Orders!H311 | ... K311: =Orders!K311 | L311: =VLOOKUP(D311,Products!$A$2:$F$61,3,FALSE()) | M311: =VLOOKUP(C311,Customers!$A$2:$F$301,5,FALSE()) | N311: =VLOOKUP(E311,Sales_Reps!$A$2:$E$31,3,FALSE()) | O311: =VLOOKUP(D311,Products!$A$2:$F$61,4,FALSE()) | P311: =VLOOKUP(C311,Customers!$A$2:$F$301,3,FALSE()) | Q311: =UPPER(TRIM(K311)) | R311: =(G311-O311)/G311 | S311: =VLOOKUP(D311,Products!$A$2:$F$61,6,FALSE())
A312: =Orders!A312 | B312: =Orders!B312 | C312: =Orders!C312 | D312: =Orders!D312 | E312: =Orders!E312 | F312: =Orders!F312 | G312: =Orders!G312 | H312: =Orders!H312 | ... K312: =Orders!K312 | L312: =VLOOKUP(D312,Products!$A$2:$F$61,3,FALSE()) | M312: =VLOOKUP(C312,Customers!$A$2:$F$301,5,FALSE()) | N312: =VLOOKUP(E312,Sales_Reps!$A$2:$E$31,3,FALSE()) | O312: =VLOOKUP(D312,Products!$A$2:$F$61,4,FALSE()) | P312: =VLOOKUP(C312,Customers!$A$2:$F$301,3,FALSE()) | Q312: =UPPER(TRIM(K312)) | R312: =(G312-O312)/G312 | S312: =VLOOKUP(D312,Products!$A$2:$F$61,6,FALSE())
A313: =Orders!A313 | B313: =Orders!B313 | C313: =Orders!C313 | D313: =Orders!D313 | E313: =Orders!E313 | F313: =Orders!F313 | G313: =Orders!G313 | H313: =Orders!H313 | ... K313: =Orders!K313 | L313: =VLOOKUP(D313,Products!$A$2:$F$61,3,FALSE()) | M313: =VLOOKUP(C313,Customers!$A$2:$F$301,5,FALSE()) | N313: =VLOOKUP(E313,Sales_Reps!$A$2:$E$31,3,FALSE()) | O313: =VLOOKUP(D313,Products!$A$2:$F$61,4,FALSE()) | P313: =VLOOKUP(C313,Customers!$A$2:$F$301,3,FALSE()) | Q313: =UPPER(TRIM(K313)) | R313: =(G313-O313)/G313 | S313: =VLOOKUP(D313,Products!$A$2:$F$61,6,FALSE())
... A2001: =Orders!A2001 | B2001: =Orders!B2001 | C2001: =Orders!C2001 | D2001: =Orders!D2001 | E2001: =Orders!E2001 | F2001: =Orders!F2001 | G2001: =Orders!G2001 | H2001: =Orders!H2001 | ... K2001: =Orders!K2001 | L2001: =VLOOKUP(D2001,Products!$A$2:$F$61,3,FALSE()) | M2001: =VLOOKUP(C2001,Customers!$A$2:$F$301,5,FALSE()) | N2001: =VLOOKUP(E2001,Sales_Reps!$A$2:$E$31,3,FALSE()) | O2001: =VLOOKUP(D2001,Products!$A$2:$F$61,4,FALSE()) | P2001: =VLOOKUP(C2001,Customers!$A$2:$F$301,3,FALSE()) | Q2001: =UPPER(TRIM(K2001)) | R2001: =(G2001-O2001)/G2001 | S2001: =VLOOKUP(D2001,Products!$A$2:$F$61,6,FALSE())

Sheet Pivot_Analysis
A1: Order Month | B1: R001 | C1: R002 | D1: R003 | E1: R004 | F1: R005 | G1: R006 | H1: R007 | I1: R008 | J1: R009 | K1: R010 | L1: R011 | M1: R012 | N1: R013 | O1: R014 | P1: R015 | Q1: R016 | R1: R017 | S1: R018 | T1: R019 | U1: R020 | V1: R021 | W1: R022 | X1: R023 | Y1: Supporting calculations | Z1: R025 | AA1: R026 | AB1: R027 | AC1: R028 | AD1: R029 | AE1: R030 | AF1: Rep ID | AG1: Rep Total Revenue | AH1: Rep Name | AI1: West Product Total | AK1: West Product ID | AL1: West Product Name | AM1: West Revenue | AO1: Bengaluru Grocery Order Value
A2: 45292 | B2: =SUMIFS(Analysis_Helper!$I$2:$I$2001,Analysis_Helper!$E$2:$E$2001,B$1,Analysis_Helper!$B$2:$B$2001,">="&$A2,Analysis_Helper!$B$2:$B$2001,"<"&EDATE($A2,1)) | C2: =SUMIFS(Analysis_Helper!$I$2:$I$2001,Analysis_Helper!$E$2:$E$2001,C$1,Analysis_Helper!$B$2:$B$2001,">="&$A2,Analysis_Helper!$B$2:$B$2001,"<"&EDATE($A2,1)) | D2: =SUMIFS(Analysis_Helper!$I$2:$I$2001,Analysis_Helper!$E$2:$E$2001,D$1,Analysis_Helper!$B$2:$B$2001,">="&$A2,Analysis_Helper!$B$2:$B$2001,"<"&EDATE($A2,1)) | E2: =SUMIFS(Analysis_Helper!$I$2:$I$2001,Analysis_Helper!$E$2:$E$2001,E$1,Analysis_Helper!$B$2:$B$2001,">="&$A2,Analysis_Helper!$B$2:$B$2001,"<"&EDATE($A2,1)) | F2: =SUMIFS(Analysis_Helper!$I$2:$I$2001,Analysis_Helper!$E$2:$E$2001,F$1,Analysis_Helper!$B$2:$B$2001,">="&$A2,Analysis_Helper!$B$2:$B$2001,"<"&EDATE($A2,1)) | G2: =SUMIFS(Analysis_Helper!$I$2:$I$2001,Analysis_Helper!$E$2:$E$2001,G$1,Analysis_Helper!$B$2:$B$2001,">="&$A2,Analysis_Helper!$B$2:$B$2001,"<"&EDATE($A2,1)) | H2: =SUMIFS(Analysis_Helper!$I$2:$I$2001,Analysis_Helper!$E$2:$E$2001,H$1,Analysis_Helper!$B$2:$B$2001,">="&$A2,Analysis_Helper!$B$2:$B$2001,"<"&EDATE($A2,1)) | I2: =SUMIFS(Analysis_Helper!$I$2:$I$2001,Analysis_Helper!$E$2:$E$2001,I$1,Analysis_Helper!$B$2:$B$2001,">="&$A2,Analysis_Helper!$B$2:$B$2001,"<"&EDATE($A2,1)) | ... X2: =SUMIFS(Analysis_Helper!$I$2:$I$2001,Analysis_Helper!$E$2:$E$2001,X$1,Analysis_Helper!$B$2:$B$2001,">="&$A2,Analysis_Helper!$B$2:$B$2001,"<"&EDATE($A2,1)) | Y2: Static/formula-based pivot outputs are provided here because openpyxl cannot create native Excel PivotTable objects. The question cells contain recalculating formulas. | Z2: =SUMIFS(Analysis_Helper!$I$2:$I$2001,Analysis_Helper!$E$2:$E$2001,Z$1,Analysis_Helper!$B$2:$B$2001,">="&$A2,Analysis_Helper!$B$2:$B$2001,"<"&EDATE($A2,1)) | AA2: =SUMIFS(Analysis_Helper!$I$2:$I$2001,Analysis_Helper!$E$2:$E$2001,AA$1,Analysis_Helper!$B$2:$B$2001,">="&$A2,Analysis_Helper!$B$2:$B$2001,"<"&EDATE($A2,1)) | AB2: =SUMIFS(Analysis_Helper!$I$2:$I$2001,Analysis_Helper!$E$2:$E$2001,AB$1,Analysis_Helper!$B$2:$B$2001,">="&$A2,Analysis_Helper!$B$2:$B$2001,"<"&EDATE($A2,1)) | AC2: =SUMIFS(Analysis_Helper!$I$2:$I$2001,Analysis_Helper!$E$2:$E$2001,AC$1,Analysis_Helper!$B$2:$B$2001,">="&$A2,Analysis_Helper!$B$2:$B$2001,"<"&EDATE($A2,1)) | AD2: =SUMIFS(Analysis_Helper!$I$2:$I$2001,Analysis_Helper!$E$2:$E$2001,AD$1,Analysis_Helper!$B$2:$B$2001,">="&$A2,Analysis_Helper!$B$2:$B$2001,"<"&EDATE($A2,1)) | AE2: =SUMIFS(Analysis_Helper!$I$2:$I$2001,Analysis_Helper!$E$2:$E$2001,AE$1,Analysis_Helper!$B$2:$B$2001,">="&$A2,Analysis_Helper!$B$2:$B$2001,"<"&EDATE($A2,1)) | AF2: R001 | AG2: =SUMIF(Analysis_Helper!$E$2:$E$2001,AF2,Analysis_Helper!$I$2:$I$2001) | AH2: =VLOOKUP(AF2,Sales_Reps!$A$2:$B$31,2,FALSE()) | AK2: PROD-001 | AL2: =VLOOKUP(AK2,Products!$A$2:$B$61,2,FALSE()) | AM2: =SUMIFS(Analysis_Helper!$I$2:$I$2001,Analysis_Helper!$D$2:$D$2001,AK2,Analysis_Helper!$N$2:$N$2001,"West") | AO2: =IF(AND(Analysis_Helper!Q2="BENGALURU",Analysis_Helper!L2="Grocery"),Analysis_Helper!I2,0)
A3: 45323 | B3: =SUMIFS(Analysis_Helper!$I$2:$I$2001,Analysis_Helper!$E$2:$E$2001,B$1,Analysis_Helper!$B$2:$B$2001,">="&$A3,Analysis_Helper!$B$2:$B$2001,"<"&EDATE($A3,1)) | C3: =SUMIFS(Analysis_Helper!$I$2:$I$2001,Analysis_Helper!$E$2:$E$2001,C$1,Analysis_Helper!$B$2:$B$2001,">="&$A3,Analysis_Helper!$B$2:$B$2001,"<"&EDATE($A3,1)) | D3: =SUMIFS(Analysis_Helper!$I$2:$I$2001,Analysis_Helper!$E$2:$E$2001,D$1,Analysis_Helper!$B$2:$B$2001,">="&$A3,Analysis_Helper!$B$2:$B$2001,"<"&EDATE($A3,1)) | E3: =SUMIFS(Analysis_Helper!$I$2:$I$2001,Analysis_Helper!$E$2:$E$2001,E$1,Analysis_Helper!$B$2:$B$2001,">="&$A3,Analysis_Helper!$B$2:$B$2001,"<"&EDATE($A3,1)) | F3: =SUMIFS(Analysis_Helper!$I$2:$I$2001,Analysis_Helper!$E$2:$E$2001,F$1,Analysis_Helper!$B$2:$B$2001,">="&$A3,Analysis_Helper!$B$2:$B$2001,"<"&EDATE($A3,1)) | G3: =SUMIFS(Analysis_Helper!$I$2:$I$2001,Analysis_Helper!$E$2:$E$2001,G$1,Analysis_Helper!$B$2:$B$2001,">="&$A3,Analysis_Helper!$B$2:$B$2001,"<"&EDATE($A3,1)) | H3: =SUMIFS(Analysis_Helper!$I$2:$I$2001,Analysis_Helper!$E$2:$E$2001,H$1,Analysis_Helper!$B$2:$B$2001,">="&$A3,Analysis_Helper!$B$2:$B$2001,"<"&EDATE($A3,1)) | I3: =SUMIFS(Analysis_Helper!$I$2:$I$2001,Analysis_Helper!$E$2:$E$2001,I$1,Analysis_Helper!$B$2:$B$2001,">="&$A3,Analysis_Helper!$B$2:$B$2001,"<"&EDATE($A3,1)) | ... AE3: =SUMIFS(Analysis_Helper!$I$2:$I$2001,Analysis_Helper!$E$2:$E$2001,AE$1,Analysis_Helper!$B$2:$B$2001,">="&$A3,Analysis_Helper!$B$2:$B$2001,"<"&EDATE($A3,1)) | AF3: R002 | AG3: =SUMIF(Analysis_Helper!$E$2:$E$2001,AF3,Analysis_Helper!$I$2:$I$2001) | AH3: =VLOOKUP(AF3,Sales_Reps!$A$2:$B$31,2,FALSE()) | AK3: PROD-002 | AL3: =VLOOKUP(AK3,Products!$A$2:$B$61,2,FALSE()) | AM3: =SUMIFS(Analysis_Helper!$I$2:$I$2001,Analysis_Helper!$D$2:$D$2001,AK3,Analysis_Helper!$N$2:$N$2001,"West") | AO3: =IF(AND(Analysis_Helper!Q3="BENGALURU",Analysis_Helper!L3="Grocery"),Analysis_Helper!I3,0)
A4: 45352 | B4: =SUMIFS(Analysis_Helper!$I$2:$I$2001,Analysis_Helper!$E$2:$E$2001,B$1,Analysis_Helper!$B$2:$B$2001,">="&$A4,Analysis_Helper!$B$2:$B$2001,"<"&EDATE($A4,1)) | C4: =SUMIFS(Analysis_Helper!$I$2:$I$2001,Analysis_Helper!$E$2:$E$2001,C$1,Analysis_Helper!$B$2:$B$2001,">="&$A4,Analysis_Helper!$B$2:$B$2001,"<"&EDATE($A4,1)) | D4: =SUMIFS(Analysis_Helper!$I$2:$I$2001,Analysis_Helper!$E$2:$E$2001,D$1,Analysis_Helper!$B$2:$B$2001,">="&$A4,Analysis_Helper!$B$2:$B$2001,"<"&EDATE($A4,1)) | E4: =SUMIFS(Analysis_Helper!$I$2:$I$2001,Analysis_Helper!$E$2:$E$2001,E$1,Analysis_Helper!$B$2:$B$2001,">="&$A4,Analysis_Helper!$B$2:$B$2001,"<"&EDATE($A4,1)) | F4: =SUMIFS(Analysis_Helper!$I$2:$I$2001,Analysis_Helper!$E$2:$E$2001,F$1,Analysis_Helper!$B$2:$B$2001,">="&$A4,Analysis_Helper!$B$2:$B$2001,"<"&EDATE($A4,1)) | G4: =SUMIFS(Analysis_Helper!$I$2:$I$2001,Analysis_Helper!$E$2:$E$2001,G$1,Analysis_Helper!$B$2:$B$2001,">="&$A4,Analysis_Helper!$B$2:$B$2001,"<"&EDATE($A4,1)) | H4: =SUMIFS(Analysis_Helper!$I$2:$I$2001,Analysis_Helper!$E$2:$E$2001,H$1,Analysis_Helper!$B$2:$B$2001,">="&$A4,Analysis_Helper!$B$2:$B$2001,"<"&EDATE($A4,1)) | I4: =SUMIFS(Analysis_Helper!$I$2:$I$2001,Analysis_Helper!$E$2:$E$2001,I$1,Analysis_Helper!$B$2:$B$2001,">="&$A4,Analysis_Helper!$B$2:$B$2001,"<"&EDATE($A4,1)) | ... AE4: =SUMIFS(Analysis_Helper!$I$2:$I$2001,Analysis_Helper!$E$2:$E$2001,AE$1,Analysis_Helper!$B$2:$B$2001,">="&$A4,Analysis_Helper!$B$2:$B$2001,"<"&EDATE($A4,1)) | AF4: R003 | AG4: =SUMIF(Analysis_Helper!$E$2:$E$2001,AF4,Analysis_Helper!$I$2:$I$2001) | AH4: =VLOOKUP(AF4,Sales_Reps!$A$2:$B$31,2,FALSE()) | AK4: PROD-003 | AL4: =VLOOKUP(AK4,Products!$A$2:$B$61,2,FALSE()) | AM4: =SUMIFS(Analysis_Helper!$I$2:$I$2001,Analysis_Helper!$D$2:$D$2001,AK4,Analysis_Helper!$N$2:$N$2001,"West") | AO4: =IF(AND(Analysis_Helper!Q4="BENGALURU",Analysis_Helper!L4="Grocery"),Analysis_Helper!I4,0)
A5: 45383 | B5: =SUMIFS(Analysis_Helper!$I$2:$I$2001,Analysis_Helper!$E$2:$E$2001,B$1,Analysis_Helper!$B$2:$B$2001,">="&$A5,Analysis_Helper!$B$2:$B$2001,"<"&EDATE($A5,1)) | C5: =SUMIFS(Analysis_Helper!$I$2:$I$2001,Analysis_Helper!$E$2:$E$2001,C$1,Analysis_Helper!$B$2:$B$2001,">="&$A5,Analysis_Helper!$B$2:$B$2001,"<"&EDATE($A5,1)) | D5: =SUMIFS(Analysis_Helper!$I$2:$I$2001,Analysis_Helper!$E$2:$E$2001,D$1,Analysis_Helper!$B$2:$B$2001,">="&$A5,Analysis_Helper!$B$2:$B$2001,"<"&EDATE($A5,1)) | E5: =SUMIFS(Analysis_Helper!$I$2:$I$2001,Analysis_Helper!$E$2:$E$2001,E$1,Analysis_Helper!$B$2:$B$2001,">="&$A5,Analysis_Helper!$B$2:$B$2001,"<"&EDATE($A5,1)) | F5: =SUMIFS(Analysis_Helper!$I$2:$I$2001,Analysis_Helper!$E$2:$E$2001,F$1,Analysis_Helper!$B$2:$B$2001,">="&$A5,Analysis_Helper!$B$2:$B$2001,"<"&EDATE($A5,1)) | G5: =SUMIFS(Analysis_Helper!$I$2:$I$2001,Analysis_Helper!$E$2:$E$2001,G$1,Analysis_Helper!$B$2:$B$2001,">="&$A5,Analysis_Helper!$B$2:$B$2001,"<"&EDATE($A5,1)) | H5: =SUMIFS(Analysis_Helper!$I$2:$I$2001,Analysis_Helper!$E$2:$E$2001,H$1,Analysis_Helper!$B$2:$B$2001,">="&$A5,Analysis_Helper!$B$2:$B$2001,"<"&EDATE($A5,1)) | I5: =SUMIFS(Analysis_Helper!$I$2:$I$2001,Analysis_Helper!$E$2:$E$2001,I$1,Analysis_Helper!$B$2:$B$2001,">="&$A5,Analysis_Helper!$B$2:$B$2001,"<"&EDATE($A5,1)) | ... AE5: =SUMIFS(Analysis_Helper!$I$2:$I$2001,Analysis_Helper!$E$2:$E$2001,AE$1,Analysis_Helper!$B$2:$B$2001,">="&$A5,Analysis_Helper!$B$2:$B$2001,"<"&EDATE($A5,1)) | AF5: R004 | AG5: =SUMIF(Analysis_Helper!$E$2:$E$2001,AF5,Analysis_Helper!$I$2:$I$2001) | AH5: =VLOOKUP(AF5,Sales_Reps!$A$2:$B$31,2,FALSE()) | AK5: PROD-004 | AL5: =VLOOKUP(AK5,Products!$A$2:$B$61,2,FALSE()) | AM5: =SUMIFS(Analysis_Helper!$I$2:$I$2001,Analysis_Helper!$D$2:$D$2001,AK5,Analysis_Helper!$N$2:$N$2001,"West") | AO5: =IF(AND(Analysis_Helper!Q5="BENGALURU",Analysis_Helper!L5="Grocery"),Analysis_Helper!I5,0)
A6: 45413 | B6: =SUMIFS(Analysis_Helper!$I$2:$I$2001,Analysis_Helper!$E$2:$E$2001,B$1,Analysis_Helper!$B$2:$B$2001,">="&$A6,Analysis_Helper!$B$2:$B$2001,"<"&EDATE($A6,1)) | C6: =SUMIFS(Analysis_Helper!$I$2:$I$2001,Analysis_Helper!$E$2:$E$2001,C$1,Analysis_Helper!$B$2:$B$2001,">="&$A6,Analysis_Helper!$B$2:$B$2001,"<"&EDATE($A6,1)) | D6: =SUMIFS(Analysis_Helper!$I$2:$I$2001,Analysis_Helper!$E$2:$E$2001,D$1,Analysis_Helper!$B$2:$B$2001,">="&$A6,Analysis_Helper!$B$2:$B$2001,"<"&EDATE($A6,1)) | E6: =SUMIFS(Analysis_Helper!$I$2:$I$2001,Analysis_Helper!$E$2:$E$2001,E$1,Analysis_Helper!$B$2:$B$2001,">="&$A6,Analysis_Helper!$B$2:$B$2001,"<"&EDATE($A6,1)) | F6: =SUMIFS(Analysis_Helper!$I$2:$I$2001,Analysis_Helper!$E$2:$E$2001,F$1,Analysis_Helper!$B$2:$B$2001,">="&$A6,Analysis_Helper!$B$2:$B$2001,"<"&EDATE($A6,1)) | G6: =SUMIFS(Analysis_Helper!$I$2:$I$2001,Analysis_Helper!$E$2:$E$2001,G$1,Analysis_Helper!$B$2:$B$2001,">="&$A6,Analysis_Helper!$B$2:$B$2001,"<"&EDATE($A6,1)) | H6: =SUMIFS(Analysis_Helper!$I$2:$I$2001,Analysis_Helper!$E$2:$E$2001,H$1,Analysis_Helper!$B$2:$B$2001,">="&$A6,Analysis_Helper!$B$2:$B$2001,"<"&EDATE($A6,1)) | I6: =SUMIFS(Analysis_Helper!$I$2:$I$2001,Analysis_Helper!$E$2:$E$2001,I$1,Analysis_Helper!$B$2:$B$2001,">="&$A6,Analysis_Helper!$B$2:$B$2001,"<"&EDATE($A6,1)) | ... AE6: =SUMIFS(Analysis_Helper!$I$2:$I$2001,Analysis_Helper!$E$2:$E$2001,AE$1,Analysis_Helper!$B$2:$B$2001,">="&$A6,Analysis_Helper!$B$2:$B$2001,"<"&EDATE($A6,1)) | AF6: R005 | AG6: =SUMIF(Analysis_Helper!$E$2:$E$2001,AF6,Analysis_Helper!$I$2:$I$2001) | AH6: =VLOOKUP(AF6,Sales_Reps!$A$2:$B$31,2,FALSE()) | AK6: PROD-005 | AL6: =VLOOKUP(AK6,Products!$A$2:$B$61,2,FALSE()) | AM6: =SUMIFS(Analysis_Helper!$I$2:$I$2001,Analysis_Helper!$D$2:$D$2001,AK6,Analysis_Helper!$N$2:$N$2001,"West") | AO6: =IF(AND(Analysis_Helper!Q6="BENGALURU",Analysis_Helper!L6="Grocery"),Analysis_Helper!I6,0)
A7: 45444 | B7: =SUMIFS(Analysis_Helper!$I$2:$I$2001,Analysis_Helper!$E$2:$E$2001,B$1,Analysis_Helper!$B$2:$B$2001,">="&$A7,Analysis_Helper!$B$2:$B$2001,"<"&EDATE($A7,1)) | C7: =SUMIFS(Analysis_Helper!$I$2:$I$2001,Analysis_Helper!$E$2:$E$2001,C$1,Analysis_Helper!$B$2:$B$2001,">="&$A7,Analysis_Helper!$B$2:$B$2001,"<"&EDATE($A7,1)) | D7: =SUMIFS(Analysis_Helper!$I$2:$I$2001,Analysis_Helper!$E$2:$E$2001,D$1,Analysis_Helper!$B$2:$B$2001,">="&$A7,Analysis_Helper!$B$2:$B$2001,"<"&EDATE($A7,1)) | E7: =SUMIFS(Analysis_Helper!$I$2:$I$2001,Analysis_Helper!$E$2:$E$2001,E$1,Analysis_Helper!$B$2:$B$2001,">="&$A7,Analysis_Helper!$B$2:$B$2001,"<"&EDATE($A7,1)) | F7: =SUMIFS(Analysis_Helper!$I$2:$I$2001,Analysis_Helper!$E$2:$E$2001,F$1,Analysis_Helper!$B$2:$B$2001,">="&$A7,Analysis_Helper!$B$2:$B$2001,"<"&EDATE($A7,1)) | G7: =SUMIFS(Analysis_Helper!$I$2:$I$2001,Analysis_Helper!$E$2:$E$2001,G$1,Analysis_Helper!$B$2:$B$2001,">="&$A7,Analysis_Helper!$B$2:$B$2001,"<"&EDATE($A7,1)) | H7: =SUMIFS(Analysis_Helper!$I$2:$I$2001,Analysis_Helper!$E$2:$E$2001,H$1,Analysis_Helper!$B$2:$B$2001,">="&$A7,Analysis_Helper!$B$2:$B$2001,"<"&EDATE($A7,1)) | I7: =SUMIFS(Analysis_Helper!$I$2:$I$2001,Analysis_Helper!$E$2:$E$2001,I$1,Analysis_Helper!$B$2:$B$2001,">="&$A7,Analysis_Helper!$B$2:$B$2001,"<"&EDATE($A7,1)) | ... AE7: =SUMIFS(Analysis_Helper!$I$2:$I$2001,Analysis_Helper!$E$2:$E$2001,AE$1,Analysis_Helper!$B$2:$B$2001,">="&$A7,Analysis_Helper!$B$2:$B$2001,"<"&EDATE($A7,1)) | AF7: R006 | AG7: =SUMIF(Analysis_Helper!$E$2:$E$2001,AF7,Analysis_Helper!$I$2:$I$2001) | AH7: =VLOOKUP(AF7,Sales_Reps!$A$2:$B$31,2,FALSE()) | AK7: PROD-006 | AL7: =VLOOKUP(AK7,Products!$A$2:$B$61,2,FALSE()) | AM7: =SUMIFS(Analysis_Helper!$I$2:$I$2001,Analysis_Helper!$D$2:$D$2001,AK7,Analysis_Helper!$N$2:$N$2001,"West") | AO7: =IF(AND(Analysis_Helper!Q7="BENGALURU",Analysis_Helper!L7="Grocery"),Analysis_Helper!I7,0)
A8: 45474 | B8: =SUMIFS(Analysis_Helper!$I$2:$I$2001,Analysis_Helper!$E$2:$E$2001,B$1,Analysis_Helper!$B$2:$B$2001,">="&$A8,Analysis_Helper!$B$2:$B$2001,"<"&EDATE($A8,1)) | C8: =SUMIFS(Analysis_Helper!$I$2:$I$2001,Analysis_Helper!$E$2:$E$2001,C$1,Analysis_Helper!$B$2:$B$2001,">="&$A8,Analysis_Helper!$B$2:$B$2001,"<"&EDATE($A8,1)) | D8: =SUMIFS(Analysis_Helper!$I$2:$I$2001,Analysis_Helper!$E$2:$E$2001,D$1,Analysis_Helper!$B$2:$B$2001,">="&$A8,Analysis_Helper!$B$2:$B$2001,"<"&EDATE($A8,1)) | E8: =SUMIFS(Analysis_Helper!$I$2:$I$2001,Analysis_Helper!$E$2:$E$2001,E$1,Analysis_Helper!$B$2:$B$2001,">="&$A8,Analysis_Helper!$B$2:$B$2001,"<"&EDATE($A8,1)) | F8: =SUMIFS(Analysis_Helper!$I$2:$I$2001,Analysis_Helper!$E$2:$E$2001,F$1,Analysis_Helper!$B$2:$B$2001,">="&$A8,Analysis_Helper!$B$2:$B$2001,"<"&EDATE($A8,1)) | G8: =SUMIFS(Analysis_Helper!$I$2:$I$2001,Analysis_Helper!$E$2:$E$2001,G$1,Analysis_Helper!$B$2:$B$2001,">="&$A8,Analysis_Helper!$B$2:$B$2001,"<"&EDATE($A8,1)) | H8: =SUMIFS(Analysis_Helper!$I$2:$I$2001,Analysis_Helper!$E$2:$E$2001,H$1,Analysis_Helper!$B$2:$B$2001,">="&$A8,Analysis_Helper!$B$2:$B$2001,"<"&EDATE($A8,1)) | I8: =SUMIFS(Analysis_Helper!$I$2:$I$2001,Analysis_Helper!$E$2:$E$2001,I$1,Analysis_Helper!$B$2:$B$2001,">="&$A8,Analysis_Helper!$B$2:$B$2001,"<"&EDATE($A8,1)) | ... AE8: =SUMIFS(Analysis_Helper!$I$2:$I$2001,Analysis_Helper!$E$2:$E$2001,AE$1,Analysis_Helper!$B$2:$B$2001,">="&$A8,Analysis_Helper!$B$2:$B$2001,"<"&EDATE($A8,1)) | AF8: R007 | AG8: =SUMIF(Analysis_Helper!$E$2:$E$2001,AF8,Analysis_Helper!$I$2:$I$2001) | AH8: =VLOOKUP(AF8,Sales_Reps!$A$2:$B$31,2,FALSE()) | AK8: PROD-007 | AL8: =VLOOKUP(AK8,Products!$A$2:$B$61,2,FALSE()) | AM8: =SUMIFS(Analysis_Helper!$I$2:$I$2001,Analysis_Helper!$D$2:$D$2001,AK8,Analysis_Helper!$N$2:$N$2001,"West") | AO8: =IF(AND(Analysis_Helper!Q8="BENGALURU",Analysis_Helper!L8="Grocery"),Analysis_Helper!I8,0)
A9: 45505 | B9: =SUMIFS(Analysis_Helper!$I$2:$I$2001,Analysis_Helper!$E$2:$E$2001,B$1,Analysis_Helper!$B$2:$B$2001,">="&$A9,Analysis_Helper!$B$2:$B$2001,"<"&EDATE($A9,1)) | C9: =SUMIFS(Analysis_Helper!$I$2:$I$2001,Analysis_Helper!$E$2:$E$2001,C$1,Analysis_Helper!$B$2:$B$2001,">="&$A9,Analysis_Helper!$B$2:$B$2001,"<"&EDATE($A9,1)) | D9: =SUMIFS(Analysis_Helper!$I$2:$I$2001,Analysis_Helper!$E$2:$E$2001,D$1,Analysis_Helper!$B$2:$B$2001,">="&$A9,Analysis_Helper!$B$2:$B$2001,"<"&EDATE($A9,1)) | E9: =SUMIFS(Analysis_Helper!$I$2:$I$2001,Analysis_Helper!$E$2:$E$2001,E$1,Analysis_Helper!$B$2:$B$2001,">="&$A9,Analysis_Helper!$B$2:$B$2001,"<"&EDATE($A9,1)) | F9: =SUMIFS(Analysis_Helper!$I$2:$I$2001,Analysis_Helper!$E$2:$E$2001,F$1,Analysis_Helper!$B$2:$B$2001,">="&$A9,Analysis_Helper!$B$2:$B$2001,"<"&EDATE($A9,1)) | G9: =SUMIFS(Analysis_Helper!$I$2:$I$2001,Analysis_Helper!$E$2:$E$2001,G$1,Analysis_Helper!$B$2:$B$2001,">="&$A9,Analysis_Helper!$B$2:$B$2001,"<"&EDATE($A9,1)) | H9: =SUMIFS(Analysis_Helper!$I$2:$I$2001,Analysis_Helper!$E$2:$E$2001,H$1,Analysis_Helper!$B$2:$B$2001,">="&$A9,Analysis_Helper!$B$2:$B$2001,"<"&EDATE($A9,1)) | I9: =SUMIFS(Analysis_Helper!$I$2:$I$2001,Analysis_Helper!$E$2:$E$2001,I$1,Analysis_Helper!$B$2:$B$2001,">="&$A9,Analysis_Helper!$B$2:$B$2001,"<"&EDATE($A9,1)) | ... AE9: =SUMIFS(Analysis_Helper!$I$2:$I$2001,Analysis_Helper!$E$2:$E$2001,AE$1,Analysis_Helper!$B$2:$B$2001,">="&$A9,Analysis_Helper!$B$2:$B$2001,"<"&EDATE($A9,1)) | AF9: R008 | AG9: =SUMIF(Analysis_Helper!$E$2:$E$2001,AF9,Analysis_Helper!$I$2:$I$2001) | AH9: =VLOOKUP(AF9,Sales_Reps!$A$2:$B$31,2,FALSE()) | AK9: PROD-008 | AL9: =VLOOKUP(AK9,Products!$A$2:$B$61,2,FALSE()) | AM9: =SUMIFS(Analysis_Helper!$I$2:$I$2001,Analysis_Helper!$D$2:$D$2001,AK9,Analysis_Helper!$N$2:$N$2001,"West") | AO9: =IF(AND(Analysis_Helper!Q9="BENGALURU",Analysis_Helper!L9="Grocery"),Analysis_Helper!I9,0)
A10: 45536 | B10: =SUMIFS(Analysis_Helper!$I$2:$I$2001,Analysis_Helper!$E$2:$E$2001,B$1,Analysis_Helper!$B$2:$B$2001,">="&$A10,Analysis_Helper!$B$2:$B$2001,"<"&EDATE($A10,1)) | C10: =SUMIFS(Analysis_Helper!$I$2:$I$2001,Analysis_Helper!$E$2:$E$2001,C$1,Analysis_Helper!$B$2:$B$2001,">="&$A10,Analysis_Helper!$B$2:$B$2001,"<"&EDATE($A10,1)) | D10: =SUMIFS(Analysis_Helper!$I$2:$I$2001,Analysis_Helper!$E$2:$E$2001,D$1,Analysis_Helper!$B$2:$B$2001,">="&$A10,Analysis_Helper!$B$2:$B$2001,"<"&EDATE($A10,1)) | E10: =SUMIFS(Analysis_Helper!$I$2:$I$2001,Analysis_Helper!$E$2:$E$2001,E$1,Analysis_Helper!$B$2:$B$2001,">="&$A10,Analysis_Helper!$B$2:$B$2001,"<"&EDATE($A10,1)) | F10: =SUMIFS(Analysis_Helper!$I$2:$I$2001,Analysis_Helper!$E$2:$E$2001,F$1,Analysis_Helper!$B$2:$B$2001,">="&$A10,Analysis_Helper!$B$2:$B$2001,"<"&EDATE($A10,1)) | G10: =SUMIFS(Analysis_Helper!$I$2:$I$2001,Analysis_Helper!$E$2:$E$2001,G$1,Analysis_Helper!$B$2:$B$2001,">="&$A10,Analysis_Helper!$B$2:$B$2001,"<"&EDATE($A10,1)) | H10: =SUMIFS(Analysis_Helper!$I$2:$I$2001,Analysis_Helper!$E$2:$E$2001,H$1,Analysis_Helper!$B$2:$B$2001,">="&$A10,Analysis_Helper!$B$2:$B$2001,"<"&EDATE($A10,1)) | I10: =SUMIFS(Analysis_Helper!$I$2:$I$2001,Analysis_Helper!$E$2:$E$2001,I$1,Analysis_Helper!$B$2:$B$2001,">="&$A10,Analysis_Helper!$B$2:$B$2001,"<"&EDATE($A10,1)) | ... AE10: =SUMIFS(Analysis_Helper!$I$2:$I$2001,Analysis_Helper!$E$2:$E$2001,AE$1,Analysis_Helper!$B$2:$B$2001,">="&$A10,Analysis_Helper!$B$2:$B$2001,"<"&EDATE($A10,1)) | AF10: R009 | AG10: =SUMIF(Analysis_Helper!$E$2:$E$2001,AF10,Analysis_Helper!$I$2:$I$2001) | AH10: =VLOOKUP(AF10,Sales_Reps!$A$2:$B$31,2,FALSE()) | AK10: PROD-009 | AL10: =VLOOKUP(AK10,Products!$A$2:$B$61,2,FALSE()) | AM10: =SUMIFS(Analysis_Helper!$I$2:$I$2001,Analysis_Helper!$D$2:$D$2001,AK10,Analysis_Helper!$N$2:$N$2001,"West") | AO10: =IF(AND(Analysis_Helper!Q10="BENGALURU",Analysis_Helper!L10="Grocery"),Analysis_Helper!I10,0)
A11: 45566 | B11: =SUMIFS(Analysis_Helper!$I$2:$I$2001,Analysis_Helper!$E$2:$E$2001,B$1,Analysis_Helper!$B$2:$B$2001,">="&$A11,Analysis_Helper!$B$2:$B$2001,"<"&EDATE($A11,1)) | C11: =SUMIFS(Analysis_Helper!$I$2:$I$2001,Analysis_Helper!$E$2:$E$2001,C$1,Analysis_Helper!$B$2:$B$2001,">="&$A11,Analysis_Helper!$B$2:$B$2001,"<"&EDATE($A11,1)) | D11: =SUMIFS(Analysis_Helper!$I$2:$I$2001,Analysis_Helper!$E$2:$E$2001,D$1,Analysis_Helper!$B$2:$B$2001,">="&$A11,Analysis_Helper!$B$2:$B$2001,"<"&EDATE($A11,1)) | E11: =SUMIFS(Analysis_Helper!$I$2:$I$2001,Analysis_Helper!$E$2:$E$2001,E$1,Analysis_Helper!$B$2:$B$2001,">="&$A11,Analysis_Helper!$B$2:$B$2001,"<"&EDATE($A11,1)) | F11: =SUMIFS(Analysis_Helper!$I$2:$I$2001,Analysis_Helper!$E$2:$E$2001,F$1,Analysis_Helper!$B$2:$B$2001,">="&$A11,Analysis_Helper!$B$2:$B$2001,"<"&EDATE($A11,1)) | G11: =SUMIFS(Analysis_Helper!$I$2:$I$2001,Analysis_Helper!$E$2:$E$2001,G$1,Analysis_Helper!$B$2:$B$2001,">="&$A11,Analysis_Helper!$B$2:$B$2001,"<"&EDATE($A11,1)) | H11: =SUMIFS(Analysis_Helper!$I$2:$I$2001,Analysis_Helper!$E$2:$E$2001,H$1,Analysis_Helper!$B$2:$B$2001,">="&$A11,Analysis_Helper!$B$2:$B$2001,"<"&EDATE($A11,1)) | I11: =SUMIFS(Analysis_Helper!$I$2:$I$2001,Analysis_Helper!$E$2:$E$2001,I$1,Analysis_Helper!$B$2:$B$2001,">="&$A11,Analysis_Helper!$B$2:$B$2001,"<"&EDATE($A11,1)) | ... AE11: =SUMIFS(Analysis_Helper!$I$2:$I$2001,Analysis_Helper!$E$2:$E$2001,AE$1,Analysis_Helper!$B$2:$B$2001,">="&$A11,Analysis_Helper!$B$2:$B$2001,"<"&EDATE($A11,1)) | AF11: R010 | AG11: =SUMIF(Analysis_Helper!$E$2:$E$2001,AF11,Analysis_Helper!$I$2:$I$2001) | AH11: =VLOOKUP(AF11,Sales_Reps!$A$2:$B$31,2,FALSE()) | AK11: PROD-010 | AL11: =VLOOKUP(AK11,Products!$A$2:$B$61,2,FALSE()) | AM11: =SUMIFS(Analysis_Helper!$I$2:$I$2001,Analysis_Helper!$D$2:$D$2001,AK11,Analysis_Helper!$N$2:$N$2001,"West") | AO11: =IF(AND(Analysis_Helper!Q11="BENGALURU",Analysis_Helper!L11="Grocery"),Analysis_Helper!I11,0)
